<?xml version='1.0'?>

<robot name="mark2" xmlns:xacro="http://www.ros.org/wiki/xacro">

  <xacro:include filename="$(find mark2_description)/urdf/mark2.gazebo" />
  <xacro:include filename="$(find mark2_description)/urdf/materials.xacro" />
  <xacro:include filename="$(find mark2_description)/urdf/macros.xacro" />

  <link name="base_link">
    <inertial>
      <origin
        xyz="-0.0216892711019691 0.0103354525192359 -2.11356546216501E-05"
        rpy="0 0 0" />
      <mass
        value="18.0131886031404" />
      <inertia
        ixx="0.0634208971678187"
        ixy="0.00171443755856836"
        ixz="-1.08883604791302E-05"
        iyy="0.122914143505658"
        iyz="-7.40778606255006E-06"
        izz="0.0722386849657522" />
    </inertial>
    <visual>
      <origin
        xyz="0 0 0"
        rpy="0 0 0" />
      <geometry>
        <mesh
          filename="package://mark2_description/meshes/base_link.STL" />
      </geometry>
      <material
        name="">
        <color
          rgba="0.792156862745098 0.819607843137255 0.933333333333333 1" />
      </material>
    </visual>
    <collision>
      <origin
        xyz="0 0 0"
        rpy="0 0 0" />
      <geometry>
        <mesh
          filename="package://mark2_description/meshes/base_link.STL" />
      </geometry>
    </collision>
  </link>

  <link name="FL_Wheel_Link">
    <inertial>
      <origin
        xyz="4.1633E-17 -1.5266E-16 -0.012545"
        rpy="0 0 0" />
      <mass
        value="0.16003" />
      <inertia
        ixx="0.0001273"
        ixy="-1.3285E-19"
        ixz="2.5754E-19"
        iyy="0.0001273"
        iyz="-3.9006E-19"
        izz="0.00023804" />
    </inertial>
    <visual>
      <origin
        xyz="0 0 0"
        rpy="0 0 0" />
      <geometry>
        <mesh
          filename="package://mark2_description/meshes/FL_Wheel_Link.STL" />
      </geometry>
      <material
        name="">
        <color
          rgba="0.34118 0.79216 1 1" />
      </material>
    </visual>
    <collision>
      <origin
        xyz="0 0 0"
        rpy="0 0 0" />
      <geometry>
        <mesh
          filename="package://mark2_description/meshes/FL_Wheel_Link.STL" />
      </geometry>
    </collision>
  </link>
  <joint name="FL_Wheel_Joint"
    type="continuous">
    <origin
      xyz="0.1175 0.1066 -0.039"
      rpy="1.5708 0 0" />
    <parent
      link="base_link" />
    <child
      link="FL_Wheel_Link" />
    <axis
      xyz="0 0 1" />
  </joint>

  <link name="BL_Wheel_Link">
    <inertial>
      <origin
        xyz="2.7756E-17 -6.9389E-17 -0.005545"
        rpy="0 0 0" />
      <mass
        value="0.16003" />
      <inertia
        ixx="0.0001273"
        ixy="4.652E-20"
        ixz="4.0057E-19"
        iyy="0.0001273"
        iyz="-4.1804E-19"
        izz="0.00023804" />
    </inertial>
    <visual>
      <origin
        xyz="0 0 0"
        rpy="0 0 0" />
      <geometry>
        <mesh
          filename="package://mark2_description/meshes/BL_Wheel_Link.STL" />
      </geometry>
      <material
        name="">
        <color
          rgba="0.34118 0.79216 1 1" />
      </material>
    </visual>
    <collision>
      <origin
        xyz="0 0 0"
        rpy="0 0 0" />
      <geometry>
        <mesh
          filename="package://mark2_description/meshes/BL_Wheel_Link.STL" />
      </geometry>
    </collision>
  </link>
  <joint name="BL_Wheel_Joint"
    type="fixed">
    <origin
      xyz="-0.1175 0.1136 -0.039"
      rpy="-1.5708 0 3.1416" />
    <parent
      link="base_link" />
    <child
      link="BL_Wheel_Link" />
    <axis
      xyz="0 0 1" />
  </joint>

  <link name="BR_Wheel_Link">
    <inertial>
      <origin
        xyz="2.7756E-17 -2.7756E-17 0.0055462"
        rpy="1 0 0" />
      <mass
        value="0.15999" />
      <inertia
        ixx="0.00012727"
        ixy="9.8997E-21"
        ixz="-4.0039E-19"
        iyy="0.00012727"
        iyz="3.593E-19"
        izz="0.00023798" />
    </inertial>
    <visual>
      <origin
        xyz="0 0 0"
        rpy="0 0 0" />
      <geometry>
        <mesh
          filename="package://mark2_description/meshes/BR_Wheel_Link.STL" />
      </geometry>
      <material
        name="">
        <color
          rgba="0.34118 0.79216 1 1" />
      </material>
    </visual>
    <collision>
      <origin
        xyz="0 0 0"
        rpy="0 0 0" />
      <geometry>
        <mesh
          filename="package://mark2_description/meshes/BR_Wheel_Link.STL" />
      </geometry>
    </collision>
  </link>
  <joint name="BR_Wheel_Joint"
    type="fixed">
    <origin
      xyz="-0.1175 -0.1136 -0.039"
      rpy="1.5708 0.0038768 0" />
    <parent
      link="base_link" />
    <child
      link="BR_Wheel_Link" />
    <axis
      xyz="0 0 1" />
  </joint>

  <link name="FR_Wheel_Link">
    <inertial>
      <origin
        xyz="2.7756E-17 4.1633E-17 0.012546"
        rpy="0 0 0" />
      <mass
        value="0.15999" />
      <inertia
        ixx="0.00012727"
        ixy="1.9408E-19"
        ixz="-4.5722E-19"
        iyy="0.00012727"
        iyz="4.4947E-19"
        izz="0.00023798" />
    </inertial>
    <visual>
      <origin
        xyz="0 0 0"
        rpy="0 0 0" />
      <geometry>
        <mesh
          filename="package://mark2_description/meshes/FR_Wheel_Link.STL" />
      </geometry>
      <material
        name="">
        <color
          rgba="0.34118 0.79216 1 1" />
      </material>
    </visual>
    <collision>
      <origin
        xyz="0 0 0"
        rpy="0 0 0" />
      <geometry>
        <mesh
          filename="package://mark2_description/meshes/FR_Wheel_Link.STL" />
      </geometry>
    </collision>
  </link>
  <joint name="FR_Wheel_Joint"
    type="continuous">
    <origin
      xyz="0.1175 -0.1066 -0.039"
      rpy="1.5708 -0.0038768 0" />
    <parent
      link="base_link" />
    <child
      link="FR_Wheel_Link" />
    <axis
      xyz="0 0 1" />
  </joint>

  <link name="RPLIdar_Link">
    <inertial>
      <origin
        xyz="0 0 0"
        rpy="0 0 0" />
      <mass
        value="0" />
      <inertia
        ixx="0"
        ixy="0"
        ixz="0"
        iyy="0"
        iyz="0"
        izz="0" />
    </inertial>
    <visual>
      <origin
        xyz="0 0 0"
        rpy="0 0 0" />
      <geometry>
        <mesh
          filename="package://mark2_description/meshes/RPLIdar_Link.STL" />
      </geometry>
      <material
        name="">
        <color
          rgba="1 1 1 1" />
      </material>
    </visual>
    <collision>
      <origin
        xyz="0 0 0"
        rpy="0 0 0" />
      <geometry>
        <mesh
          filename="package://mark2_description/meshes/RPLIdar_Link.STL" />
      </geometry>
    </collision>
  </link>
  <joint name="RPLIdar_Joint"
    type="fixed">
    <origin
      xyz="0.035526 0.00030663 0.079529"
      rpy="1.5708 0 3.1416" />
    <parent
      link="base_link" />
    <child
      link="RPLIdar_Link" />
    <axis
      xyz="0 0 0" />
  </joint>
</robot>
